<?xml version='1.0' encoding='utf-8'?>
<mujoco model="play_g2">
  <compiler angle="radian" meshdir="../../../meshes/" texturedir="../../meshes/" autolimits="true" />

  <default>
    <default class="robot">

      <default class="visual">
        <geom material="visualgeom" contype="0" conaffinity="0" group="2" />
      </default>
      <default class="collision">
        <geom material="collision_material" condim="3" contype="1" conaffinity="1" priority="1" group="1" solref="0.005 1" solimp="0.99 0.999 1e-05" friction="1 0.01 0.01" />
      </default>
    </default>
  </default>
   <option integrator="implicitfast" timestep="0.002" />

  <compiler angle="radian" />

  <asset>
    <material name="1" rgba="0.75294 0.75294 0.75294 1" />
    <material name="default_material" rgba="0.7 0.7 0.7 1" />
    <material name="collision_material" rgba="1.0 0.28 0.1 0.9" />
    <mesh name="base_link.STL" file="airbot_play_force/base_link.STL" />
    <mesh name="link1.STL" file="airbot_play_force/link1.STL" />
    <mesh name="link2.STL" file="airbot_play_force/link2.STL" />
    <mesh name="link3.STL" file="airbot_play_force/link3.STL" />
    <mesh name="link4.STL" file="airbot_play_force/link4.STL" />
    <mesh name="link5.STL" file="airbot_play_force/link5.STL" />
    <mesh name="link6.STL" file="airbot_play_force/link6.STL" />
    <mesh name="eef_connect_base_link.STL" file="airbot_play_force/eef_connect_base_link.STL" />
    <mesh name="g2_base_link.STL" file="airbot_play_force/g2_base_link.STL" />
    <mesh name="g2_left_link.STL" file="airbot_play_force/g2_left_link.STL" />
    <mesh name="g2_right_link.STL" file="airbot_play_force/g2_right_link.STL" />
  </asset>

  <worldbody>
    <body name="base_link" pos="0.00000000 0.00000000 0.00000000" quat="1 0 0 0" childclass="robot">
      
      
      <geom name="base_link_visual" pos="0 0 0" quat="1.0 0.0 0.0 0.0" material="1" type="mesh" mesh="base_link.STL" class="visual" />
      <body name="link1" pos="0 0 0.1127" quat="1.0 0.0 0.0 0.0">
        <joint name="joint1" type="hinge" ref="0.0" range="-3.1416 2.0944" frictionloss="4.7527200419e-01" damping="1.3995284974e-01" armature="9.9957402200e-07" axis="0 0 1" />
        <inertial pos="0.0000006887 -0.0000047165 -0.0209679991" mass="0.6069999981" fullinertia="1.0629508900e-03 1.0629508899e-03 4.9999867809e-04 -1.3385026730e-16 1.6649958352e-12 -8.7150641997e-11" />
        
        <geom name="link1_visual" pos="0 0 0" quat="1.0 0.0 0.0 0.0" material="1" type="mesh" mesh="link1.STL" class="visual" />
        <body name="link2" pos="0 0 0" quat="0.1358665314310754 0.1358711302557462 -0.6939313632833966 0.6939298124821854">
          <joint name="joint2" type="hinge" ref="0.0" frictionloss="4.6849231461e-01" damping="1.5186377225e-01" armature="1.2126607778e-02" range="-2.9671 0.17453" axis="0 0 1" />
          <inertial pos="0.1089321192 0.0106177565 -0.0249802076" mass="0.9180028873" fullinertia="9.1698617699e-03 3.0762873556e-02 2.9723708984e-02 -2.4300986094e-03 5.8305046772e-03 4.1072380331e-03" />
          <geom name="link2_collision" pos="0 0 0" quat="1.0 0.0 0.0 0.0" type="mesh" mesh="link2.STL" class="collision" />
          <geom name="link2_visual" pos="0 0 0" quat="1.0 0.0 0.0 0.0" material="1" type="mesh" mesh="link2.STL" class="visual" />
          <body name="link3" pos="0.27009 0 0" quat="0.55806023303518 0.0 0.0 0.8298004436638489">
            <joint name="joint3" type="hinge" ref="0.0" frictionloss="4.4783814305e-01" damping="1.8999819707e-01" armature="1.9403872769e-02" range="-0.087266 3.1416" axis="0 0 1" />
            <inertial pos="0.0019600457 0.1298701299 -0.0332828990" mass="0.7699999999" fullinertia="1.1724503328e-02 7.3018534962e-03 1.6977923247e-02 7.9366560269e-03 2.1602551770e-03 -2.8444318289e-03" />
            <geom name="link3_collision" pos="0 0 0" quat="1.0 0.0 0.0 0.0" type="mesh" mesh="link3.STL" class="collision" />
            <geom name="link3_visual" pos="0 0 0" quat="1.0 0.0 0.0 0.0" material="1" type="mesh" mesh="link3.STL" class="visual" />
            <body name="link4" pos="0 0.29015 0" quat="0.4999981633974483 -0.49999999999662686 -0.49999999999662686 -0.5000018366025516">
              <joint name="joint4" type="hinge" ref="0.0" frictionloss="4.3083563782e-01" damping="2.0607996511e-01" armature="1.4532998161e-02" range="-3.0107 3.0107" axis="0 0 1" />
              <inertial pos="-0.0020904548 -0.0271666925 -0.1116417422" mass="0.3948999999" fullinertia="1.8299386856e-02 2.0439619535e-02 5.5154293458e-03 -2.2679296466e-03 7.6511230636e-03 4.8499165919e-03" />
              <geom name="link4_collision" pos="0 0 0" quat="1.0 0.0 0.0 0.0" type="mesh" mesh="link4.STL" class="collision" />
              <geom name="link4_visual" pos="0 0 0" quat="1.0 0.0 0.0 0.0" material="1" type="mesh" mesh="link4.STL" class="visual" />
              <body name="link5" pos="0 0 0" quat="0.7071054825112363 0.7071080798594735 0.0 0.0">
                <joint name="joint5" type="hinge" ref="0.0" armature="7.2227231289e-03" range="-1.7628 1.7628" axis="0 0 1" damping="9.4257865188e-04" frictionloss="3.5259337994e-04" />
                <inertial pos="0.0003400662 0.0494369861 -0.0250724222" mass="0.4432999999" fullinertia="1.8175163650e-03 9.1827175344e-04 1.8115726689e-03 4.7738705871e-04 -2.0911608757e-04 4.8421803101e-04" />
                <geom name="link5_collision" pos="0 0 0" quat="1.0 0.0 0.0 0.0" type="mesh" mesh="link5.STL" class="collision" />
                <geom name="link5_visual" pos="0 0 0" quat="1.0 0.0 0.0 0.0" material="1" type="mesh" mesh="link5.STL" class="visual" />
                <body name="link6" pos="0 0 0" quat="0.7071054825112363 -0.7071080798594735 0.0 0.0">
                  <joint name="joint6" type="hinge" ref="0.0" frictionloss="4.2075540795e-01" damping="1.7846300395e-01" armature="5.0000002166e-03" range="-30107 30107" axis="0 0 1" />
                  <inertial pos="0.0062815796 -0.0044140620 0.0341968747" mass="0.1209999999" fullinertia="1.4146085030e-03 2.9751038472e-03 2.0963793624e-03 1.6828882033e-04 -1.1896773553e-03 1.2684049374e-04" />
                  <geom name="link6_collision" pos="0 0 0" quat="1.0 0.0 0.0 0.0" type="mesh" mesh="link6.STL" class="collision" />
                  <geom name="link6_visual" pos="0 0 0" quat="1.0 0.0 0.0 0.0" material="1" type="mesh" mesh="link6.STL" class="visual" />
                  <body name="eef_connect_base_link" pos="0.0 0.0 0.0955" quat="1.0 0.0 0.0 0.0">
                    
                    <geom name="eef_connect_base_link_collision" pos="0 0 0" quat="1.0 0.0 0.0 0.0" type="mesh" mesh="eef_connect_base_link.STL" class="collision" />
                    <geom name="eef_connect_base_link_visual" pos="0 0 0" quat="1.0 0.0 0.0 0.0" material="1" type="mesh" mesh="eef_connect_base_link.STL" class="visual" />
                    
                      
                      
                      
                      
                        
                        
                        
                    
                  </body>
                </body>
              </body>
            </body>
          </body>
        </body>
      </body>
      <site name="base_link_site" pos="0 0 0" quat="1 0 0 0" />
      <camera name="front_camera" mode="track" fovy="90.0" quat="4.329780281177467e-17 4.329780281177466e-17 0.7071067811865475 0.7071067811865476" pos="0.0 2.0 0.5" />
      <camera name="side_camera" mode="track" fovy="90.0" quat="-0.5 -0.4999999999999999 0.5 0.5000000000000001" pos="-2.0 0.0 0.5" />
    </body>
  </worldbody>

  <actuator>
    <motor name="joint1" joint="joint1" ctrllimited="true" ctrlrange="-20 20" />
    <motor name="joint2" joint="joint2" ctrllimited="true" ctrlrange="-20 20" />
    <motor name="joint3" joint="joint3" ctrllimited="true" ctrlrange="-20 20" />
    <motor name="joint4" joint="joint4" ctrllimited="true" ctrlrange="-20 20" />
    <motor name="joint5" joint="joint5" ctrllimited="true" ctrlrange="-20 20" />
    <motor name="joint6" joint="joint6" ctrllimited="true" ctrlrange="-20 20" />



    
  </actuator>

  <sensor>
    <jointpos name="joint1_pos" joint="joint1" />
    <jointpos name="joint2_pos" joint="joint2" />
    <jointpos name="joint3_pos" joint="joint3" />
    <jointpos name="joint4_pos" joint="joint4" />
    <jointpos name="joint5_pos" joint="joint5" />
    
    

    <jointvel name="joint1_vel" joint="joint1" />
    <jointvel name="joint2_vel" joint="joint2" />
    <jointvel name="joint3_vel" joint="joint3" />
    <jointvel name="joint4_vel" joint="joint4" />
    <jointvel name="joint5_vel" joint="joint5" />
    <jointvel name="joint6_vel" joint="joint6" />
    

    <jointactuatorfrc name="joint1_torque" joint="joint1" />
    <jointactuatorfrc name="joint2_torque" joint="joint2" />
    <jointactuatorfrc name="joint3_torque" joint="joint3" />
    <jointactuatorfrc name="joint4_torque" joint="joint4" />
    <jointactuatorfrc name="joint5_torque" joint="joint5" />
    <jointactuatorfrc name="joint6_torque" joint="joint6" />
    

    
  </sensor>
</mujoco>