<?xml version='1.0' encoding='utf-8'?>
<mujoco model="play_g2">
  <compiler angle="radian" meshdir="../../../meshes/" texturedir="../../meshes/" autolimits="true" />

  <default>
    <default class="robot">

      <default class="visual">
        <geom material="visualgeom" contype="0" conaffinity="0" group="2" />
      </default>
      <default class="collision">
        <geom material="collision_material" condim="3" contype="1" conaffinity="1" priority="1" group="1" solref="0.005 1" solimp="0.99 0.999 1e-05" friction="1 0.01 0.01" />
      </default>
    </default>
  </default>
   <option integrator="implicitfast" timestep="0.002" />

  <compiler angle="radian" />

  <asset>
    <material name="1" rgba="0.75294 0.75294 0.75294 1" />
    <material name="default_material" rgba="0.7 0.7 0.7 1" />
    <material name="collision_material" rgba="1.0 0.28 0.1 0.9" />
    <mesh name="base_link.STL" file="airbot_play_force/base_link.STL" />
    <mesh name="link1.STL" file="airbot_play_force/link1.STL" />
    <mesh name="link2.STL" file="airbot_play_force/link2.STL" />
    <mesh name="link3.STL" file="airbot_play_force/link3.STL" />
    <mesh name="link4.STL" file="airbot_play_force/link4.STL" />
    <mesh name="link5.STL" file="airbot_play_force/link5.STL" />
    <mesh name="link6.STL" file="airbot_play_force/link6.STL" />
    <mesh name="eef_connect_base_link.STL" file="airbot_play_force/eef_connect_base_link.STL" />
    <mesh name="g2_base_link.STL" file="airbot_play_force/g2_base_link.STL" />
    <mesh name="g2_left_link.STL" file="airbot_play_force/g2_left_link.STL" />
    <mesh name="g2_right_link.STL" file="airbot_play_force/g2_right_link.STL" />
  </asset>

  <worldbody>
    <body name="base_link" pos="0.00000000 0.00000000 0.00000000" quat="1 0 0 0" childclass="robot">
      
      
      <geom name="base_link_visual" pos="0 0 0" quat="1.0 0.0 0.0 0.0" material="1" type="mesh" mesh="base_link.STL" class="visual" />
      <body name="link1" pos="0 0 0.1127" quat="1.0 0.0 0.0 0.0">
        <joint name="joint1" type="hinge" ref="0.0" range="-3.1416 2.0944" armature="1.0187882503e-05" axis="0 0 1" damping="4.2622715968e-06" frictionloss="1.3259171692e-01" />
        <inertial pos="0.0000000038 -0.0000000261 -0.0209824325" mass="0.6070770902" fullinertia="1.0628856724e-03 1.0628856725e-03 2.5579251832e-04 -1.2984964348e-14 1.2569887631e-14 -5.7932511842e-13" />
        
        <geom name="link1_visual" pos="0 0 0" quat="1.0 0.0 0.0 0.0" material="1" type="mesh" mesh="link1.STL" class="visual" />
        <body name="link2" pos="0 0 0" quat="0.1358665314310754 0.1358711302557462 -0.6939313632833966 0.6939298124821854">
          <joint name="joint2" type="hinge" ref="0.0" armature="6.6310050297e-03" range="-2.9671 0.17453" axis="0 0 1" damping="5.3031747818e-06" frictionloss="3.6127997398e-01" />
          <inertial pos="0.0990102516 0.0150675447 -0.0049395874" mass="1.0097999258" fullinertia="5.2759866784e-04 5.2725527125e-04 5.1840419511e-04 -1.5077347907e-06 -1.3176472801e-06 5.9952309838e-07" />
          <geom name="link2_collision" pos="0 0 0" quat="1.0 0.0 0.0 0.0" type="mesh" mesh="link2.STL" class="collision" />
          <geom name="link2_visual" pos="0 0 0" quat="1.0 0.0 0.0 0.0" material="1" type="mesh" mesh="link2.STL" class="visual" />
          <body name="link3" pos="0.27009 0 0" quat="0.55806023303518 0.0 0.0 0.8298004436638489">
            <joint name="joint3" type="hinge" ref="0.0" armature="6.7449331441e-06" range="-0.087266 3.1416" axis="0 0 1" damping="5.7304050077e-06" frictionloss="3.0930045472e-01" />
            <inertial pos="0.0054575728 0.1298717762 -0.0044073319" mass="0.7699784095" fullinertia="1.2345660508e-03 2.0021990200e-03 2.6250514118e-03 -9.6540015022e-04 -2.1461488584e-04 -1.4678021233e-04" />
            <geom name="link3_collision" pos="0 0 0" quat="1.0 0.0 0.0 0.0" type="mesh" mesh="link3.STL" class="collision" />
            <geom name="link3_visual" pos="0 0 0" quat="1.0 0.0 0.0 0.0" material="1" type="mesh" mesh="link3.STL" class="visual" />
            <body name="link4" pos="0 0.29015 0" quat="0.4999981633974483 -0.49999999999662686 -0.49999999999662686 -0.5000018366025516">
              <joint name="joint4" type="hinge" ref="0.0" armature="2.9851079857e-06" range="-3.0107 3.0107" axis="0 0 1" damping="1.3487458679e-02" frictionloss="9.0103985398e-02" />
              <inertial pos="-0.0002116311 -0.0114420103 -0.1022551073" mass="0.3948781203" fullinertia="3.4931700844e-04 3.6427823923e-04 1.8507082380e-04 5.2295296820e-06 -1.7523210525e-06 7.9725327253e-07" />
              <geom name="link4_collision" pos="0 0 0" quat="1.0 0.0 0.0 0.0" type="mesh" mesh="link4.STL" class="collision" />
              <geom name="link4_visual" pos="0 0 0" quat="1.0 0.0 0.0 0.0" material="1" type="mesh" mesh="link4.STL" class="visual" />
              <body name="link5" pos="0 0 0" quat="0.7071054825112363 0.7071080798594735 0.0 0.0">
                <joint name="joint5" type="hinge" ref="0.0" armature="2.0797925534e-03" range="-1.7628 1.7628" axis="0 0 1" damping="2.4609529227e-02" frictionloss="5.7269614457e-02" />
                <inertial pos="0.0015325714 0.0469710332 -0.0149987227" mass="0.4432781804" fullinertia="5.0268553749e-04 4.9481886122e-04 4.8683443860e-04 -9.0942423446e-06 -1.0420835757e-05 -1.2773600146e-06" />
                <geom name="link5_collision" pos="0 0 0" quat="1.0 0.0 0.0 0.0" type="mesh" mesh="link5.STL" class="collision" />
                <geom name="link5_visual" pos="0 0 0" quat="1.0 0.0 0.0 0.0" material="1" type="mesh" mesh="link5.STL" class="visual" />
                <body name="link6" pos="0 0 0" quat="0.7071054825112363 -0.7071080798594735 0.0 0.0">
                  <joint name="joint6" type="hinge" ref="0.0" armature="2.8871863111e-03" range="-30107 30107" axis="0 0 1" damping="2.7783381731e-02" frictionloss="5.3426711074e-02" />
                  <inertial pos="0.0089783578 -0.0188232476 0.0509650194" mass="0.1209782233" fullinertia="4.6695112739e-04 4.7473615376e-04 4.4640843756e-04 -2.7796258745e-06 4.6233771202e-06 -3.6887473289e-06" />
                  <geom name="link6_collision" pos="0 0 0" quat="1.0 0.0 0.0 0.0" type="mesh" mesh="link6.STL" class="collision" />
                  <geom name="link6_visual" pos="0 0 0" quat="1.0 0.0 0.0 0.0" material="1" type="mesh" mesh="link6.STL" class="visual" />
                  <body name="eef_connect_base_link" pos="0.0 0.0 0.0955" quat="1.0 0.0 0.0 0.0">
                    
                    <geom name="eef_connect_base_link_collision" pos="0 0 0" quat="1.0 0.0 0.0 0.0" type="mesh" mesh="eef_connect_base_link.STL" class="collision" />
                    <geom name="eef_connect_base_link_visual" pos="0 0 0" quat="1.0 0.0 0.0 0.0" material="1" type="mesh" mesh="eef_connect_base_link.STL" class="visual" />
                    
                      
                      
                      
                      
                        
                        
                        
                    
                  </body>
                </body>
              </body>
            </body>
          </body>
        </body>
      </body>
      <site name="base_link_site" pos="0 0 0" quat="1 0 0 0" />
      <camera name="front_camera" mode="track" fovy="90.0" quat="4.329780281177467e-17 4.329780281177466e-17 0.7071067811865475 0.7071067811865476" pos="0.0 2.0 0.5" />
      <camera name="side_camera" mode="track" fovy="90.0" quat="-0.5 -0.4999999999999999 0.5 0.5000000000000001" pos="-2.0 0.0 0.5" />
    </body>
  </worldbody>

  <actuator>
    <motor name="joint1" joint="joint1" ctrllimited="true" ctrlrange="-20 20" />
    <motor name="joint2" joint="joint2" ctrllimited="true" ctrlrange="-20 20" />
    <motor name="joint3" joint="joint3" ctrllimited="true" ctrlrange="-20 20" />
    <motor name="joint4" joint="joint4" ctrllimited="true" ctrlrange="-20 20" />
    <motor name="joint5" joint="joint5" ctrllimited="true" ctrlrange="-20 20" />
    <motor name="joint6" joint="joint6" ctrllimited="true" ctrlrange="-20 20" />



    
  </actuator>

  <sensor>
    <jointpos name="joint1_pos" joint="joint1" />
    <jointpos name="joint2_pos" joint="joint2" />
    <jointpos name="joint3_pos" joint="joint3" />
    <jointpos name="joint4_pos" joint="joint4" />
    <jointpos name="joint5_pos" joint="joint5" />
    
    

    <jointvel name="joint1_vel" joint="joint1" />
    <jointvel name="joint2_vel" joint="joint2" />
    <jointvel name="joint3_vel" joint="joint3" />
    <jointvel name="joint4_vel" joint="joint4" />
    <jointvel name="joint5_vel" joint="joint5" />
    <jointvel name="joint6_vel" joint="joint6" />
    

    <jointactuatorfrc name="joint1_torque" joint="joint1" />
    <jointactuatorfrc name="joint2_torque" joint="joint2" />
    <jointactuatorfrc name="joint3_torque" joint="joint3" />
    <jointactuatorfrc name="joint4_torque" joint="joint4" />
    <jointactuatorfrc name="joint5_torque" joint="joint5" />
    <jointactuatorfrc name="joint6_torque" joint="joint6" />
    

    
  </sensor>
</mujoco>