<mujoco model="play_g2">
  <compiler angle="radian" meshdir="../../../meshes/" texturedir="../../meshes/" autolimits="true" balanceinertia="true" />

  <default>
    <default class="robot">

      <default class="visual">
        <geom material="visualgeom" contype="0" conaffinity="0" group="2" />
      </default>
      <default class="collision">
        <geom material="collision_material" condim="3" contype="1" conaffinity="1" priority="1" group="1" solref="0.005 1" solimp="0.99 0.999 1e-05" friction="1 0.01 0.01" />
      </default>
    </default>
  </default>
   <option integrator="implicitfast" timestep="0.002" gravity="0 0 -9.81"/>

  <compiler angle="radian" />

  <asset>
    <material name="1" rgba="0.75294 0.75294 0.75294 1" />
    <material name="default_material" rgba="0.7 0.7 0.7 1" />
    <material name="collision_material" rgba="1.0 0.28 0.1 0.9" />
    <mesh name="base_link.STL" file="airbot_play_force/base_link.STL" />
    <mesh name="link1.STL" file="airbot_play_force/link1.STL" />
    <mesh name="link2.STL" file="airbot_play_force/link2.STL" />
    <mesh name="link3.STL" file="airbot_play_force/link3.STL" />
    <mesh name="link4.STL" file="airbot_play_force/link4.STL" />
    <mesh name="link5.STL" file="airbot_play_force/link5.STL" />
    <mesh name="link6.STL" file="airbot_play_force/link6.STL" />
    <mesh name="eef_connect_base_link.STL" file="airbot_play_force/eef_connect_base_link.STL" />
    <mesh name="g2_base_link.STL" file="airbot_play_force/g2_base_link.STL" />
    <mesh name="g2_left_link.STL" file="airbot_play_force/g2_left_link.STL" />
    <mesh name="g2_right_link.STL" file="airbot_play_force/g2_right_link.STL" />
  </asset>

  <worldbody>
    <body name="base_link" pos="0.00000000 0.00000000 0.00000000" quat="1 0 0 0" childclass="robot">
      <!-- <freejoint name="floating_base" /> -->
      <!-- <geom name="base_link_collision" pos="0 0 0" quat="1.0 0.0 0.0 0.0" type="mesh" mesh="base_link.STL" class="collision" /> -->
      <geom name="base_link_visual" pos="0 0 0" quat="1.0 0.0 0.0 0.0" material="1" type="mesh" mesh="base_link.STL" class="visual" />
      <body name="link1" pos="0 0 0.1127" quat="1.0 0.0 0.0 0.0">
        <joint name="joint1" type="hinge" ref="0.0"  range="-3.1416 2.0944" frictionloss="0.5" damping="0.1" axis="0 0 1" />
        <inertial pos="0.00014396 -0.00098536 -0.020968"  mass="0.607" fullinertia="0.0011117 0.0010136 0.0003867 1.605E-05 -1.45E-06 -7.07E-06" />
        <geom name="link1_collision" pos="0 0 0" quat="1.0 0.0 0.0 0.0" type="mesh" mesh="link1.STL" class="collision" />
        <geom name="link1_visual" pos="0 0 0" quat="1.0 0.0 0.0 0.0" material="1" type="mesh" mesh="link1.STL" class="visual" />
        <body name="link2" pos="0 0 0" quat="0.1358665314310754 0.1358711302557462 -0.6939313632833966 0.6939298124821854">
          <joint name="joint2" type="hinge" ref="0.0"  range="-2.9671 0.17453" axis="0 0 1" frictionloss="0.5" damping="0.01"/>
          <inertial pos="0.13769 0.012537 0.0044739"  mass="0.918"  fullinertia="0.00094437 0.03479442 0.03461144 0.00112155 -0.00063705 -7.45E-06" />
          <geom name="link2_collision" pos="0 0 0" quat="1.0 0.0 0.0 0.0" type="mesh" mesh="link2.STL" class="collision" />
          <geom name="link2_visual" pos="0 0 0" quat="1.0 0.0 0.0 0.0" material="1" type="mesh" mesh="link2.STL" class="visual" />
          <body name="link3" pos="0.27009 0 0" quat="0.55806023303518 0.0 0.0 0.8298004436638489">
            <joint name="joint3" type="hinge" ref="0.0"  range="-0.087266 3.1416" axis="0 0 1" frictionloss="0.5" damping="0.01"/>
            <inertial pos="1.5134E-05 0.10706 0.0082136"  mass="0.7" fullinertia="0.01565914 0.00045929 0.0154811 1.007E-05 1.02E-06 0.00010253" />
            <geom name="link3_collision" pos="0 0 0" quat="1.0 0.0 0.0 0.0" type="mesh" mesh="link3.STL" class="collision" />
            <geom name="link3_visual" pos="0 0 0" quat="1.0 0.0 0.0 0.0" material="1" type="mesh" mesh="link3.STL" class="visual" />
            <body name="link4" pos="0 0.29015 0" quat="0.4999981633974483 -0.49999999999662686 -0.49999999999662686 -0.5000018366025516">
              <joint name="joint4" type="hinge" ref="0.0"  range="-3.0107 3.0107" frictionloss="0.5" damping="0.01" axis="0 0 1" />
              <inertial pos="-1.6216E-05 0.002995 -0.019407" mass="0.359" fullinertia="0.00051773 0.00052925 0.00013681 -4E-08 1.5E-07 -4.05E-06" />
              <geom name="link4_collision" pos="0 0 0" quat="1.0 0.0 0.0 0.0" type="mesh" mesh="link4.STL" class="collision" />
              <geom name="link4_visual" pos="0 0 0" quat="1.0 0.0 0.0 0.0" material="1" type="mesh" mesh="link4.STL" class="visual" />
              <body name="link5" pos="0 0 0" quat="0.7071054825112363 0.7071080798594735 0.0 0.0">
                <joint name="joint5" type="hinge" ref="0.0"  range="-1.7628 1.7628" frictionloss="0.5" damping="0.01" axis="0 0 1" />
                <inertial pos="-4.5037E-05 0.033144 0.0024106"  mass="0.403" fullinertia="0.00116016 0.00024251 0.00108456 -3.1E-07 -2.4E-07 -4.809E-05" />
                <geom name="link5_collision" pos="0 0 0" quat="1.0 0.0 0.0 0.0" type="mesh" mesh="link5.STL" class="collision" />
                <geom name="link5_visual" pos="0 0 0" quat="1.0 0.0 0.0 0.0" material="1" type="mesh" mesh="link5.STL" class="visual" />
                <body name="link6" pos="0 0 0" quat="0.7071054825112363 -0.7071080798594735 0.0 0.0">
                  <joint name="joint6" type="hinge" ref="0.0"  range="-30107 30107" axis="0 0 1"  frictionloss="0" damping="0.5"/>
                  <inertial pos="-4.6366E-05 4.3424E-05 0.066592"  mass="0.11" fullinertia="0.00051056 0.00051056 1.73e-05 0 -3.4E-07 3.2E-07" />
                  <geom name="link6_collision" pos="0 0 0" quat="1.0 0.0 0.0 0.0" type="mesh" mesh="link6.STL" class="collision" />
                  <geom name="link6_visual" pos="0 0 0" quat="1.0 0.0 0.0 0.0" material="1" type="mesh" mesh="link6.STL" class="visual" />
                  <body name="eef_connect_base_link" pos="0.0 0.0 0.0955" quat="1.0 0.0 0.0 0.0">
                    <!-- <inertial pos="3.5687E-06 0.00020484 -0.004811" quat="1.0 0.0 0.0 0.0" mass="0.000000000000019009" fullinertia="4.0476e-06 3.9455e-06 7.498e-06" /> -->
                    <geom name="eef_connect_base_link_collision" pos="0 0 0" quat="1.0 0.0 0.0 0.0" type="mesh" mesh="eef_connect_base_link.STL" class="collision" />
                    <geom name="eef_connect_base_link_visual" pos="0 0 0" quat="1.0 0.0 0.0 0.0" material="1" type="mesh" mesh="eef_connect_base_link.STL" class="visual" />
                    <!-- <body name="g2_base_link" pos="0.0 0.0 0.0" quat="1.0 0.0 0.0 0.0"> -->
                      <!-- <inertial pos="5.9308E-05 -3.262E-05 0.041814" quat="1.0 0.0 0.0 0.0" mass="0.00000000000488" fullinertia="0.00115523 0.00137334 0.00042051" /> -->
                      <!-- <geom name="g2_base_link_collision" pos="0 0 0" quat="1.0 0.0 0.0 0.0" type="mesh" mesh="g2_base_link.STL" class="collision" /> -->
                      <!-- <geom name="g2_base_link_visual" pos="0 0 0" quat="1.0 0.0 0.0 0.0" material="1" type="mesh" mesh="g2_base_link.STL" class="visual" /> -->
                      <!-- <body name="g2_left_link" pos="0 0 0.0705" quat="0.7071054825112363 0.0 -0.7071080798594735 0.0"> -->
                        <!-- <joint name="g2_left_joint" type="slide" ref="0.0"  range="0 0.0366" axis="0 0 1" />
                        <inertial pos="0.018307 5.9636E-06 0.012505" quat="1.0 0.0 0.0 0.0" mass="0.0000000000000054004" fullinertia="2.46e-05 4.78e-05 4.892e-05" />
                        <geom name="g2_left_link_collision" pos="0 0 0" quat="1.0 0.0 0.0 0.0" type="mesh" mesh="g2_left_link.STL" class="collision" />
                        <geom name="g2_left_link_visual" pos="0 0 0" quat="1.0 0.0 0.0 0.0" material="1" type="mesh" mesh="g2_left_link.STL" class="visual" />
                      </body>
                      <body name="g2_right_link" pos="0 0 0.0705" quat="-2.5973434669646147e-06 0.707105482506466 2.597353007557415e-06 0.7071080798547033"> -->
                        <!-- <joint name="g2_right_joint" type="slide" ref="0.0"  range="0 0.0366" axis="0 0 1" /> -->
                        <!-- <inertial pos="0.018307 -6.8572E-07 0.012505" quat="1.0 0.0 0.0 0.0" mass="0.1" fullinertia="2.46e-05 4.78e-05 4.892e-05" />
                        <geom name="g2_right_link_collision" pos="0 0 0" quat="1.0 0.0 0.0 0.0" type="mesh" mesh="g2_right_link.STL" class="collision" />
                        <geom name="g2_right_link_visual" pos="0 0 0" quat="1.0 0.0 0.0 0.0" material="1" type="mesh" mesh="g2_right_link.STL" class="visual" />
                      </body> -->
                    <!-- </body> -->
                  </body>
                </body>
              </body>
            </body>
          </body>
        </body>
      </body>
      <site name="base_link_site" pos="0 0 0" quat="1 0 0 0" />
      <camera name="front_camera" mode="track" fovy="90.0" quat="4.329780281177467e-17 4.329780281177466e-17 0.7071067811865475 0.7071067811865476" pos="0.0 2.0 0.5" />
      <camera name="side_camera" mode="track" fovy="90.0" quat="-0.5 -0.4999999999999999 0.5 0.5000000000000001" pos="-2.0 0.0 0.5" />
    </body>
  </worldbody>

  <actuator>
    <motor name="joint1" joint="joint1" ctrllimited="true" ctrlrange="-10 10"/>
    <motor name="joint2" joint="joint2" ctrllimited="true" ctrlrange="-10 10"/>
    <motor name="joint3" joint="joint3" ctrllimited="true" ctrlrange="-10 10"/>
    <motor name="joint4" joint="joint4" ctrllimited="true" ctrlrange="-10 10"/>
    <motor name="joint5" joint="joint5" ctrllimited="true" ctrlrange="-10 10"/>
    <motor name="joint6" joint="joint6" ctrllimited="true" ctrlrange="-10 10"/>



    <!-- <velocity name="joint1" joint="joint1" ctrllimited="true" kv="1000"  ctrlrange="-10 10"/>
    <velocity name="joint2" joint="joint2" ctrllimited="true" kv="100"  ctrlrange="-10 10"/>
    <velocity name="joint3" joint="joint3" ctrllimited="true" kv="100"  ctrlrange="-10 10"/>
    <velocity name="joint4" joint="joint4" ctrllimited="true" kv="1000"  ctrlrange="-5 5"/>
    <velocity name="joint5" joint="joint5" ctrllimited="true" kv="1000"  ctrlrange="-5 5"/>
    <velocity name="joint6" joint="joint6" ctrllimited="true" kv="1000"  ctrlrange="-5 5"/> -->
  </actuator>

  <sensor>
    <jointpos name="joint1_pos" joint="joint1" />
    <jointpos name="joint2_pos" joint="joint2" />
    <jointpos name="joint3_pos" joint="joint3" />
    <jointpos name="joint4_pos" joint="joint4" />
    <jointpos name="joint5_pos" joint="joint5" />
    <!-- <jointpos name="joint6_pos" joint="joint6" /> -->
    <!-- <tendonpos name="gripper_pos" tendon="gripper_gear" /> -->

    <jointvel name="joint1_vel" joint="joint1" />
    <jointvel name="joint2_vel" joint="joint2" />
    <jointvel name="joint3_vel" joint="joint3" />
    <jointvel name="joint4_vel" joint="joint4" />
    <jointvel name="joint5_vel" joint="joint5" />
    <jointvel name="joint6_vel" joint="joint6" />
    <!-- <tendonvel name="gripper_vel" tendon="gripper_gear" /> -->

    <jointactuatorfrc name="joint1_torque" joint="joint1" />
    <jointactuatorfrc name="joint2_torque" joint="joint2" />
    <jointactuatorfrc name="joint3_torque" joint="joint3" />
    <jointactuatorfrc name="joint4_torque" joint="joint4" />
    <jointactuatorfrc name="joint5_torque" joint="joint5" />
    <jointactuatorfrc name="joint6_torque" joint="joint6" />
    <!-- <jointactuatorfrc name="gripper_torque" joint="endright" /> -->

    <!-- <framepos name="endpoint_pos" objtype="site" objname="endpoint" reftype="site" refname="armbase"/>
    <framequat name="endpoint_quat" objtype="site" objname="endpoint" reftype="site" refname="armbase"/>
    <framelinvel name="endpoint_vel" objtype="site" objname="endpoint" reftype="site" refname="armbase"/>
    <gyro name="endpoint_gyro" site="endpoint"/>
    <accelerometer name="endpoint_acc" site="endpoint" /> -->
  </sensor>
</mujoco>