<?xml version='1.0' encoding='utf-8'?>
<mujoco model="play_g2">
  <compiler angle="radian" meshdir="../../../meshes/" texturedir="../../meshes/" autolimits="true" />

  <default>
    <default class="robot">

      <default class="visual">
        <geom material="visualgeom" contype="0" conaffinity="0" group="2" />
      </default>
      <default class="collision">
        <geom material="collision_material" condim="3" contype="1" conaffinity="1" priority="1" group="1" solref="0.005 1" solimp="0.99 0.999 1e-05" friction="1 0.01 0.01" />
      </default>
    </default>
  </default>
   <option integrator="implicitfast" timestep="0.002" />

  <compiler angle="radian" />

  <asset>
    <material name="1" rgba="0.75294 0.75294 0.75294 1" />
    <material name="default_material" rgba="0.7 0.7 0.7 1" />
    <material name="collision_material" rgba="1.0 0.28 0.1 0.9" />
    <mesh name="base_link.STL" file="airbot_play_force/base_link.STL" />
    <mesh name="link1.STL" file="airbot_play_force/link1.STL" />
    <mesh name="link2.STL" file="airbot_play_force/link2.STL" />
    <mesh name="link3.STL" file="airbot_play_force/link3.STL" />
    <mesh name="link4.STL" file="airbot_play_force/link4.STL" />
    <mesh name="link5.STL" file="airbot_play_force/link5.STL" />
    <mesh name="link6.STL" file="airbot_play_force/link6.STL" />
    <mesh name="eef_connect_base_link.STL" file="airbot_play_force/eef_connect_base_link.STL" />
    <mesh name="g2_base_link.STL" file="airbot_play_force/g2_base_link.STL" />
    <mesh name="g2_left_link.STL" file="airbot_play_force/g2_left_link.STL" />
    <mesh name="g2_right_link.STL" file="airbot_play_force/g2_right_link.STL" />
  </asset>

  <worldbody>
    <body name="base_link" pos="0.00000000 0.00000000 0.00000000" quat="1 0 0 0" childclass="robot">
      
      
      <geom name="base_link_visual" pos="0 0 0" quat="1.0 0.0 0.0 0.0" material="1" type="mesh" mesh="base_link.STL" class="visual" />
      <body name="link1" pos="0 0 0.1127" quat="1.0 0.0 0.0 0.0">
        <joint name="joint1" type="hinge" ref="0.0" range="-3.1416 2.0944" frictionloss="1.2786265227e-01" damping="2.4188515290e-05" armature="3.3936917238e-05" axis="0 0 1" />
        <inertial pos="0.0000000023 -0.0000000158 -0.0211585464" mass="0.6080057276" fullinertia="1.0613870457e-03 1.0613870460e-03 3.1098004914e-04 -2.9938704551e-14 9.3354911043e-15 -3.2643083432e-13" />
        
        <geom name="link1_visual" pos="0 0 0" quat="1.0 0.0 0.0 0.0" material="1" type="mesh" mesh="link1.STL" class="visual" />
        <body name="link2" pos="0 0 0" quat="0.1358665314310754 0.1358711302557462 -0.6939313632833966 0.6939298124821854">
          <joint name="joint2" type="hinge" ref="0.0" frictionloss="2.0822478871e-01" damping="2.4146859233e-05" armature="2.5615860193e-05" range="-2.9671 0.17453" axis="0 0 1" />
          <inertial pos="-0.0525551480 0.0050247778 0.0026324902" mass="1.0097998010" fullinertia="6.3182928110e-04 6.5151884049e-04 6.5268220224e-04 -1.2653581719e-05 -9.2480737638e-07 6.9602365474e-06" />
          <geom name="link2_collision" pos="0 0 0" quat="1.0 0.0 0.0 0.0" type="mesh" mesh="link2.STL" class="collision" />
          <geom name="link2_visual" pos="0 0 0" quat="1.0 0.0 0.0 0.0" material="1" type="mesh" mesh="link2.STL" class="visual" />
          <body name="link3" pos="0.27009 0 0" quat="0.55806023303518 0.0 0.0 0.8298004436638489">
            <joint name="joint3" type="hinge" ref="0.0" frictionloss="1.6643204430e-01" damping="1.8471928399e-05" armature="3.0542718881e-05" range="-0.087266 3.1416" axis="0 0 1" />
            <inertial pos="0.0026807710 0.0520818272 -0.0074454595" mass="0.6300072687" fullinertia="4.7807161288e-04 2.9878873799e-04 5.2775638937e-04 9.7224081383e-06 -1.9051725857e-05 1.1617206579e-05" />
            <geom name="link3_collision" pos="0 0 0" quat="1.0 0.0 0.0 0.0" type="mesh" mesh="link3.STL" class="collision" />
            <geom name="link3_visual" pos="0 0 0" quat="1.0 0.0 0.0 0.0" material="1" type="mesh" mesh="link3.STL" class="visual" />
            <body name="link4" pos="0 0.29015 0" quat="0.4999981633974483 -0.49999999999662686 -0.49999999999662686 -0.5000018366025516">
              <joint name="joint4" type="hinge" ref="0.0" frictionloss="8.5436904248e-02" damping="1.9453733998e-02" armature="2.2721313657e-05" range="-3.0107 3.0107" axis="0 0 1" />
              <inertial pos="-0.0074447433 0.0065722206 -0.2379549944" mass="0.3231072693" fullinertia="4.7232436542e-04 5.2432124137e-04 3.0019860473e-04 4.6512763746e-05 1.9521211666e-06 -3.7186658991e-06" />
              <geom name="link4_collision" pos="0 0 0" quat="1.0 0.0 0.0 0.0" type="mesh" mesh="link4.STL" class="collision" />
              <geom name="link4_visual" pos="0 0 0" quat="1.0 0.0 0.0 0.0" material="1" type="mesh" mesh="link4.STL" class="visual" />
              <body name="link5" pos="0 0 0" quat="0.7071054825112363 0.7071080798594735 0.0 0.0">
                <joint name="joint5" type="hinge" ref="0.0" armature="5.8596540451e-03" range="-1.7628 1.7628" axis="0 0 1" damping="1.4191879580e-02" frictionloss="5.8398721526e-02" />
                <inertial pos="0.0025670720 0.0461107870 -0.0023499424" mass="0.3627113743" fullinertia="5.0060422026e-04 2.8986704452e-04 4.6036698121e-04 -1.7531725498e-05 -4.2663621425e-05 -1.2355002428e-05" />
                <geom name="link5_collision" pos="0 0 0" quat="1.0 0.0 0.0 0.0" type="mesh" mesh="link5.STL" class="collision" />
                <geom name="link5_visual" pos="0 0 0" quat="1.0 0.0 0.0 0.0" material="1" type="mesh" mesh="link5.STL" class="visual" />
                <body name="link6" pos="0 0 0" quat="0.7071054825112363 -0.7071080798594735 0.0 0.0">
                  <joint name="joint6" type="hinge" ref="0.0" frictionloss="5.3618118459e-02" damping="2.7626300411e-02" armature="1.5380374486e-04" range="-30107 30107" axis="0 0 1" />
                  <inertial pos="0.0117909641 -0.0194443689 0.0498817804" mass="0.0990108411" fullinertia="8.2719269688e-05 3.3741969148e-04 3.2641219132e-04 2.7710888092e-05 4.1917455333e-05 6.3005037925e-06" />
                  <geom name="link6_collision" pos="0 0 0" quat="1.0 0.0 0.0 0.0" type="mesh" mesh="link6.STL" class="collision" />
                  <geom name="link6_visual" pos="0 0 0" quat="1.0 0.0 0.0 0.0" material="1" type="mesh" mesh="link6.STL" class="visual" />
                  <body name="eef_connect_base_link" pos="0.0 0.0 0.0955" quat="1.0 0.0 0.0 0.0">
                    
                    <geom name="eef_connect_base_link_collision" pos="0 0 0" quat="1.0 0.0 0.0 0.0" type="mesh" mesh="eef_connect_base_link.STL" class="collision" />
                    <geom name="eef_connect_base_link_visual" pos="0 0 0" quat="1.0 0.0 0.0 0.0" material="1" type="mesh" mesh="eef_connect_base_link.STL" class="visual" />
                    
                      
                      
                      
                      
                        
                        
                        
                    
                  </body>
                </body>
              </body>
            </body>
          </body>
        </body>
      </body>
      <site name="base_link_site" pos="0 0 0" quat="1 0 0 0" />
      <camera name="front_camera" mode="track" fovy="90.0" quat="4.329780281177467e-17 4.329780281177466e-17 0.7071067811865475 0.7071067811865476" pos="0.0 2.0 0.5" />
      <camera name="side_camera" mode="track" fovy="90.0" quat="-0.5 -0.4999999999999999 0.5 0.5000000000000001" pos="-2.0 0.0 0.5" />
    </body>
  </worldbody>

  <actuator>
    <motor name="joint1" joint="joint1" ctrllimited="true" ctrlrange="-20 20" />
    <motor name="joint2" joint="joint2" ctrllimited="true" ctrlrange="-20 20" />
    <motor name="joint3" joint="joint3" ctrllimited="true" ctrlrange="-20 20" />
    <motor name="joint4" joint="joint4" ctrllimited="true" ctrlrange="-20 20" />
    <motor name="joint5" joint="joint5" ctrllimited="true" ctrlrange="-20 20" />
    <motor name="joint6" joint="joint6" ctrllimited="true" ctrlrange="-20 20" />



    
  </actuator>

  <sensor>
    <jointpos name="joint1_pos" joint="joint1" />
    <jointpos name="joint2_pos" joint="joint2" />
    <jointpos name="joint3_pos" joint="joint3" />
    <jointpos name="joint4_pos" joint="joint4" />
    <jointpos name="joint5_pos" joint="joint5" />
    
    

    <jointvel name="joint1_vel" joint="joint1" />
    <jointvel name="joint2_vel" joint="joint2" />
    <jointvel name="joint3_vel" joint="joint3" />
    <jointvel name="joint4_vel" joint="joint4" />
    <jointvel name="joint5_vel" joint="joint5" />
    <jointvel name="joint6_vel" joint="joint6" />
    

    <jointactuatorfrc name="joint1_torque" joint="joint1" />
    <jointactuatorfrc name="joint2_torque" joint="joint2" />
    <jointactuatorfrc name="joint3_torque" joint="joint3" />
    <jointactuatorfrc name="joint4_torque" joint="joint4" />
    <jointactuatorfrc name="joint5_torque" joint="joint5" />
    <jointactuatorfrc name="joint6_torque" joint="joint6" />
    

    
  </sensor>
</mujoco>