<mujoco model="play_g2">
  <default>
    <default class="robot">
      <default class="visual">
        <geom contype="0" conaffinity="0" group="2" />
      </default>
      <default class="collision">
        <geom material="collision_material" condim="3" contype="0" conaffinity="1" priority="1" group="3" solref="0.005 1" friction="1 0.01 0.01" />
        <equality solimp="0.99 0.999 1e-05" solref="0.005 1" />
      </default>
    </default>
  </default>

  <compiler angle="radian" meshdir="." balanceinertia="true" />

  <size nconmax="5000" njmax="5000" />

  <option integrator="implicitfast" />

  <worldbody>
    <body name="base_link" pos="0.00000000 0.00000000 0.00000000" childclass="robot">
      <inertial pos="-0.018345 -0.002558 0.03724" mass="1e-06" diaginertia="0.00121381 0.00164872 0.00126552" />
      <body name="link1" pos="0 0 0.1127">
        <inertial pos="0.00014396 -0.00098536 -0.020968" mass="0.607" diaginertia="0.0011117 0.0010136 0.0003867" />
        <joint name="joint1" type="hinge" range="-3.1416 2.0944" axis="0 0 1" />
        <body name="link2" quat="0.1358665314310754 0.1358711302557462 -0.6939313632833966 0.6939298124821854">
          <inertial pos="0.13769 0.012537 0.0044739" mass="0.918" diaginertia="0.00094437 0.03479442 0.03461144" />
          <joint name="joint2" type="hinge" range="-2.9671 0.17453" axis="0 0 1" />
          <body name="link3" pos="0.27009 0 0" quat="0.55806023303518 0.0 0.0 0.8298004436638489">
            <inertial pos="1.5134E-05 0.10706 0.0082136" mass="0.7" diaginertia="0.01565914 0.00045929 0.0154811" />
            <joint name="joint3" type="hinge" range="-0.087266 3.1416" axis="0 0 1" />
            <body name="link4" pos="0 0.29015 0" quat="0.4999981633974483 -0.49999999999662686 -0.49999999999662686 -0.5000018366025516">
              <inertial pos="-1.6216E-05 0.002995 -0.019407" mass="0.359" diaginertia="0.00051773 0.00052925 0.00013681" />
              <joint name="joint4" type="hinge" range="-3.0107 3.0107" axis="0 0 1" />
              <body name="link5" quat="0.7071054825112363 0.7071080798594735 0.0 0.0">
                <inertial pos="-4.5037E-05 0.033144 0.0024106" mass="0.403" diaginertia="0.00116016 0.00024251 0.00108456" />
                <joint name="joint5" type="hinge" range="-1.7628 1.7628" axis="0 0 1" />
                <body name="link6" quat="0.7071054825112363 -0.7071080798594735 0.0 0.0">
                  <inertial pos="-4.6366E-05 4.3424E-05 0.066592" mass="0.11" diaginertia="0.00051056 0.00051056 1.73e-05" />
                  <joint name="joint6" type="hinge" range="-3.0107 3.0107" axis="0 0 1" />
                  <body name="eef_connect_base_link" pos="0.0 0.0 0.0955">
                    <inertial pos="3.5687E-06 0.00020484 -0.004811" mass="1e-06" diaginertia="4.0476e-06 3.9455e-06 7.498e-06" />
                  </body>
                </body>
              </body>
            </body>
          </body>
        </body>
      </body>
      <site name="base_link_site" pos="0 0 0" quat="1 0 0 0" />
    </body>
    <light pos="0 0 2." dir="0 0 -1" directional="true" />
  </worldbody>

  <asset>
    <material name="default_material" rgba="0.7 0.7 0.7 1" />
    <material name="collision_material" rgba="1.0 0.28 0.1 0.9" />
  </asset>

  <actuator>
    <motor name="joint1" joint="joint1" />
    <motor name="joint2" joint="joint2" />
    <motor name="joint3" joint="joint3" />
    <motor name="joint4" joint="joint4" />
    <motor name="joint5" joint="joint5" />
    <motor name="joint6" joint="joint6" />
  </actuator>
</mujoco>