<?xml version='1.0' encoding='utf-8'?>
<mujoco model="play_g2">
  <compiler angle="radian" meshdir="../../../meshes/" texturedir="../../meshes/" autolimits="true" />

  <default>
    <default class="robot">

      <default class="visual">
        <geom material="visualgeom" contype="0" conaffinity="0" group="2" />
      </default>
      <default class="collision">
        <geom material="collision_material" condim="3" contype="1" conaffinity="1" priority="1" group="1" solref="0.005 1" solimp="0.99 0.999 1e-05" friction="1 0.01 0.01" />
      </default>
    </default>
  </default>
   <option integrator="implicitfast" timestep="0.002" />

  <compiler angle="radian" />

  <asset>
    <material name="1" rgba="0.75294 0.75294 0.75294 1" />
    <material name="default_material" rgba="0.7 0.7 0.7 1" />
    <material name="collision_material" rgba="1.0 0.28 0.1 0.9" />
    <mesh name="base_link.STL" file="airbot_play_force/base_link.STL" />
    <mesh name="link1.STL" file="airbot_play_force/link1.STL" />
    <mesh name="link2.STL" file="airbot_play_force/link2.STL" />
    <mesh name="link3.STL" file="airbot_play_force/link3.STL" />
    <mesh name="link4.STL" file="airbot_play_force/link4.STL" />
    <mesh name="link5.STL" file="airbot_play_force/link5.STL" />
    <mesh name="link6.STL" file="airbot_play_force/link6.STL" />
    <mesh name="eef_connect_base_link.STL" file="airbot_play_force/eef_connect_base_link.STL" />
    <mesh name="g2_base_link.STL" file="airbot_play_force/g2_base_link.STL" />
    <mesh name="g2_left_link.STL" file="airbot_play_force/g2_left_link.STL" />
    <mesh name="g2_right_link.STL" file="airbot_play_force/g2_right_link.STL" />
  </asset>

  <worldbody>
    <body name="base_link" pos="0.00000000 0.00000000 0.00000000" quat="1 0 0 0" childclass="robot">
      
      
      <geom name="base_link_visual" pos="0 0 0" quat="1.0 0.0 0.0 0.0" material="1" type="mesh" mesh="base_link.STL" class="visual" />
      <body name="link1" pos="0 0 0.1127" quat="1.0 0.0 0.0 0.0">
        <joint name="joint1" type="hinge" ref="0.0" range="-3.1416 2.0944" armature="2.0235057333e-05" axis="0 0 1" damping="2.7689621234e-05" frictionloss="1.3733385393e-01" />
        <inertial pos="0.0000000027 -0.0000000182 -0.0210487956" mass="0.6074527935" fullinertia="1.0625308736e-03 1.0625308739e-03 2.8935350410e-04 -2.2704415538e-14 9.8124735950e-15 -3.8838068772e-13" />
        
        <geom name="link1_visual" pos="0 0 0" quat="1.0 0.0 0.0 0.0" material="1" type="mesh" mesh="link1.STL" class="visual" />
        <body name="link2" pos="0 0 0" quat="0.1358665314310754 0.1358711302557462 -0.6939313632833966 0.6939298124821854">
          <joint name="joint2" type="hinge" ref="0.0" armature="5.2015169755e-03" range="-2.9671 0.17453" axis="0 0 1" damping="3.5388029924e-05" frictionloss="1.7907317606e-01" />
          <inertial pos="-0.0534804440 0.0063886221 0.0026358987" mass="1.0097999115" fullinertia="5.5997973066e-04 5.8725939925e-04 5.4921611842e-04 -9.5934049711e-06 -1.4878354014e-06 6.9016566443e-06" />
          <geom name="link2_collision" pos="0 0 0" quat="1.0 0.0 0.0 0.0" type="mesh" mesh="link2.STL" class="collision" />
          <geom name="link2_visual" pos="0 0 0" quat="1.0 0.0 0.0 0.0" material="1" type="mesh" mesh="link2.STL" class="visual" />
          <body name="link3" pos="0.27009 0 0" quat="0.55806023303518 0.0 0.0 0.8298004436638489">
            <joint name="joint3" type="hinge" ref="0.0" armature="1.6722495361e-05" range="-0.087266 3.1416" axis="0 0 1" damping="2.3143533101e-05" frictionloss="1.6960326627e-01" />
            <inertial pos="0.0038255094 0.0659249131 -0.0004193723" mass="0.6300033272" fullinertia="5.6216302174e-03 1.0551620212e-03 6.0054244727e-03 -1.4984649077e-03 -1.1816700536e-04 -3.4404605182e-04" />
            <geom name="link3_collision" pos="0 0 0" quat="1.0 0.0 0.0 0.0" type="mesh" mesh="link3.STL" class="collision" />
            <geom name="link3_visual" pos="0 0 0" quat="1.0 0.0 0.0 0.0" material="1" type="mesh" mesh="link3.STL" class="visual" />
            <body name="link4" pos="0 0.29015 0" quat="0.4999981633974483 -0.49999999999662686 -0.49999999999662686 -0.5000018366025516">
              <joint name="joint4" type="hinge" ref="0.0" armature="8.8930283948e-06" range="-3.0107 3.0107" axis="0 0 1" damping="1.1984010889e-02" frictionloss="9.0125770134e-02" />
              <inertial pos="-0.0088763930 0.0184604140 -0.2673092830" mass="0.3231033785" fullinertia="4.4927100004e-03 4.4928948828e-03 2.2906692555e-04 -6.4010030764e-05 5.7125422066e-04 5.6616766213e-04" />
              <geom name="link4_collision" pos="0 0 0" quat="1.0 0.0 0.0 0.0" type="mesh" mesh="link4.STL" class="collision" />
              <geom name="link4_visual" pos="0 0 0" quat="1.0 0.0 0.0 0.0" material="1" type="mesh" mesh="link4.STL" class="visual" />
              <body name="link5" pos="0 0 0" quat="0.7071054825112363 0.7071080798594735 0.0 0.0">
                <joint name="joint5" type="hinge" ref="0.0" armature="1.1390221227e-02" range="-1.7628 1.7628" axis="0 0 1" damping="6.1735200211e-03" frictionloss="6.2949314860e-02" />
                <inertial pos="0.0025186266 0.0434286267 0.0106662192" mass="0.3627034830" fullinertia="5.9234668540e-04 5.7963505302e-04 5.4299815662e-04 -5.3856991521e-07 -1.0160126363e-05 7.4865234380e-07" />
                <geom name="link5_collision" pos="0 0 0" quat="1.0 0.0 0.0 0.0" type="mesh" mesh="link5.STL" class="collision" />
                <geom name="link5_visual" pos="0 0 0" quat="1.0 0.0 0.0 0.0" material="1" type="mesh" mesh="link5.STL" class="visual" />
                <body name="link6" pos="0 0 0" quat="0.7071054825112363 -0.7071080798594735 0.0 0.0">
                  <joint name="joint6" type="hinge" ref="0.0" armature="4.1888160655e-03" range="-30107 30107" axis="0 0 1" damping="2.4374285132e-02" frictionloss="5.4350471179e-02" />
                  <inertial pos="0.0132677251 -0.0116898498 0.0519113021" mass="0.0990034947" fullinertia="1.1625150831e-03 1.7718931534e-03 1.1587278644e-03 -1.7001205408e-05 -5.8123104163e-04 -7.6033861808e-06" />
                  <geom name="link6_collision" pos="0 0 0" quat="1.0 0.0 0.0 0.0" type="mesh" mesh="link6.STL" class="collision" />
                  <geom name="link6_visual" pos="0 0 0" quat="1.0 0.0 0.0 0.0" material="1" type="mesh" mesh="link6.STL" class="visual" />
                  <body name="eef_connect_base_link" pos="0.0 0.0 0.0955" quat="1.0 0.0 0.0 0.0">
                    
                    <geom name="eef_connect_base_link_collision" pos="0 0 0" quat="1.0 0.0 0.0 0.0" type="mesh" mesh="eef_connect_base_link.STL" class="collision" />
                    <geom name="eef_connect_base_link_visual" pos="0 0 0" quat="1.0 0.0 0.0 0.0" material="1" type="mesh" mesh="eef_connect_base_link.STL" class="visual" />
                    
                      
                      
                      
                      
                        
                        
                        
                    
                  </body>
                </body>
              </body>
            </body>
          </body>
        </body>
      </body>
      <site name="base_link_site" pos="0 0 0" quat="1 0 0 0" />
      <camera name="front_camera" mode="track" fovy="90.0" quat="4.329780281177467e-17 4.329780281177466e-17 0.7071067811865475 0.7071067811865476" pos="0.0 2.0 0.5" />
      <camera name="side_camera" mode="track" fovy="90.0" quat="-0.5 -0.4999999999999999 0.5 0.5000000000000001" pos="-2.0 0.0 0.5" />
    </body>
  </worldbody>

  <actuator>
    <motor name="joint1" joint="joint1" ctrllimited="true" ctrlrange="-20 20" />
    <motor name="joint2" joint="joint2" ctrllimited="true" ctrlrange="-20 20" />
    <motor name="joint3" joint="joint3" ctrllimited="true" ctrlrange="-20 20" />
    <motor name="joint4" joint="joint4" ctrllimited="true" ctrlrange="-20 20" />
    <motor name="joint5" joint="joint5" ctrllimited="true" ctrlrange="-20 20" />
    <motor name="joint6" joint="joint6" ctrllimited="true" ctrlrange="-20 20" />



    
  </actuator>

  <sensor>
    <jointpos name="joint1_pos" joint="joint1" />
    <jointpos name="joint2_pos" joint="joint2" />
    <jointpos name="joint3_pos" joint="joint3" />
    <jointpos name="joint4_pos" joint="joint4" />
    <jointpos name="joint5_pos" joint="joint5" />
    
    

    <jointvel name="joint1_vel" joint="joint1" />
    <jointvel name="joint2_vel" joint="joint2" />
    <jointvel name="joint3_vel" joint="joint3" />
    <jointvel name="joint4_vel" joint="joint4" />
    <jointvel name="joint5_vel" joint="joint5" />
    <jointvel name="joint6_vel" joint="joint6" />
    

    <jointactuatorfrc name="joint1_torque" joint="joint1" />
    <jointactuatorfrc name="joint2_torque" joint="joint2" />
    <jointactuatorfrc name="joint3_torque" joint="joint3" />
    <jointactuatorfrc name="joint4_torque" joint="joint4" />
    <jointactuatorfrc name="joint5_torque" joint="joint5" />
    <jointactuatorfrc name="joint6_torque" joint="joint6" />
    

    
  </sensor>
</mujoco>